Workbook
Name SearchTomas: #REF!
Name Tomas: #REF!
Name NazwanyZakres1: Players!$G:$G

Sheet Players
A1: playername | B1: username | C1: ranking | D1: percentile | E1: place | F1: warcount | G1: nationality | H1: clanhistory | I1: cup1on1edition1 | J1: meeting | K1: cup3on3 | L1: active | M1: ban | N1: lastwar | O1: fpw | P1: fpwmax | Q1: fpwmin | R1: last30days | S1: last365days | T1: lastwarpc | U1: s4_22wars | V1: s4_22fpw
A2: Zielony | B2: zielony | C2: 1368.1071 | D2: =NORMDIST(C2,1000,STDEV($C$2:$C$39)+0.00001,TRUE) -> 0.99999585 | F2: =COUNTIF('Match History'!A:BK,"zielony") -> 776 | G2: PL | H2: suRe, stArs | I2: 3 | K2: 1 | L2: =AND($N2<>"no war", $N2>=DATE(2022, 12, 31)-30, $M2<>TRUE) -> TRUE | M2: FALSE | N2: {=IF(F2=0, "no war", INDEX('Match History'!A:A, MAX(MAX(('Match History'!B:B=B2)*(ROW('Match History'!B:B))),MAX(('Match History'!F:F=B2)*(ROW('Match History'!F:F))),MAX(('Match History'!J:J=B2)*(ROW('Match History'!J:J))),MAX(('Match History'!N:N=B2)*(ROW('Match History'!N:N))),MAX(('Match History'!R:R=B2)*(ROW('Match History'!R:R))),MAX(('Match History'!V:V=B2)*(ROW('Match History'!V:V))),MAX(('Match History'!Z:Z=B2)*(ROW('Match History'!Z:Z))),MAX(('Match History'!AD:AD=B2)*(ROW('Match History'!AD:AD))),MAX(('Match History'!AH:AH=B2)*(ROW('Match History'!AH:AH))),MAX(('Match History'!AL:AL=B2)*(ROW('Match History'!AL:AL))),MAX(('Match History'!AV:AV=B2)*(ROW('Match History'!AV:AV))),MAX(('Match History'!AZ:AZ=B2)*(ROW('Match History'!AZ:AZ))),MAX(('Match History'!BD:BD=B2)*(ROW('Match History'!BD:BD))),MAX(('Match History'!BH:BH=B2)*(ROW('Match History'!BH:BH)))), 1))} -> 44925.925 | O2: =(SUMIF('Match History'!B:B,B2,'Match History'!D:D)+SUMIF('Match History'!F:F,B2,'Match History'!H:H)+SUMIF('Match History'!J:J,B2,'Match History'!L:L)+SUMIF('Match History'!N:N,B2,'Match History'!P:P)+SUMIF('Match History'!R:R,B2,'Match History'!T:T)+SUMIF('Match History'!V:V,B2,'Match History'!X:X)+SUMIF('Match History'!Z:Z,B2,'Match History'!AB:AB)+SUMIF('Match History'!AD:AD,B2,'Match History'!AF:AF)+SUMIF('Match History'!AH:AH,B2,'Match History'!AJ:AJ)+SUMIF('Match History'!AL:AL,B2,'Match History'!AN:AN)+SUMIF('Match History'!AV:AV,B2,'Match History'!AX:AX)+SUMIF('Match History'!AZ:AZ,B2,'Match History'!BB:BB)+SUMIF('Match History'!BD:BD,B2,'Match History'!BF:BF)+SUMIF('Match History'!BH:BH,B2,'Match History'!BJ:BJ))/IF(F2=0,1,F2) -> 29.64433 | P2: {=MAX(MAX(IF('Match History'!B:B=B2,'Match History'!D:D,)),MAX(IF('Match History'!F:F=B2,'Match History'!H:H,)),MAX(IF('Match History'!J:J=B2,'Match History'!L:L,)),MAX(IF('Match History'!N:N=B2,'Match History'!P:P,)),MAX(IF('Match History'!R:R=B2,'Match History'!T:T,)),MAX(IF('Match History'!V:V=B2,'Match History'!X:X,)),MAX(IF('Match History'!Z:Z=B2,'Match History'!AB:AB,)),MAX(IF('Match History'!AD:AD=B2,'Match History'!AF:AF,)),MAX(IF('Match History'!AH:AH=B2,'Match History'!AJ:AJ,)),MAX(IF('Match History'!AL:AL=B2,'Match History'!AN:AN,)),MAX(IF('Match History'!AV:AV=B2,'Match History'!AX:AX,)),MAX(IF('Match History'!AZ:AZ=B2,'Match History'!BB:BB,)),MAX(IF('Match History'!BD:BD=B2,'Match History'!BF:BF,)),MAX(IF('Match History'!BH:BH=B2,'Match History'!BJ:BJ,)))} -> 93 | Q2: {=IF(F2=0,0,MIN(MIN(IF('Match History'!B:B=B2,'Match History'!D:D,999)),MIN(IF('Match History'!F:F=B2,'Match History'!H:H,999)),MIN(IF('Match History'!J:J=B2,'Match History'!L:L,999)),MIN(IF('Match History'!N:N=B2,'Match History'!P:P,999)),MIN(IF('Match History'!R:R=B2,'Match History'!T:T,999)),MIN(IF('Match History'!V:V=B2,'Match History'!X:X,999)),MIN(IF('Match History'!Z:Z=B2,'Match History'!AB:AB,999)),MIN(IF('Match History'!AD:AD=B2,'Match History'!AF:AF,999)),MIN(IF('Match History'!AH:AH=B2,'Match History'!AJ:AJ,999)),MIN(IF('Match History'!AL:AL=B2,'Match History'!AN:AN,999)),MIN(IF('Match History'!AV:AV=B2,'Match History'!AX:AX,999)),MIN(IF('Match History'!AZ:AZ=B2,'Match History'!BB:BB,999)),MIN(IF('Match History'!BD:BD=B2,'Match History'!BF:BF,999)),MIN(IF('Match History'!BH:BH=B2,'Match History'!BJ:BJ,999))))} -> 10 | R2: =COUNTIFS('Match History'!B:B,B2,'Match History'!A:A,">="&(DATE(2022,12,31)-30))+COUNTIFS('Match History'!F:F,B2,'Match History'!A:A,">="&(DATE(2022,12,31)-30))+COUNTIFS('Match History'!J:J,B2,'Match History'!A:A,">="&(DATE(2022,12,31)-30))+COUNTIFS('Match History'!N:N,B2,'Match History'!A:A,">="&(DATE(2022,12,31)-30))+COUNTIFS('Match History'!R:R,B2,'Match History'!A:A,">="&(DATE(2022,12,31)-30))+COUNTIFS('Match History'!V:V,B2,'Match History'!A:A,">="&(DATE(2022,12,31)-30))+COUNTIFS('Match History'!Z:Z,B2,'Match History'!A:A,">="&(DATE(2022,12,31)-30))+COUNTIFS('Match History'!AD:AD,B2,'Match History'!A:A,">="&(DATE(2022,12,31)-30))+COUNTIFS('Match History'!AH:AH,B2,'Match History'!A:A,">="&(DATE(2022,12,31)-30))+COUNTIFS('Match History'!AL:AL,B2,'Match History'!A:A,">="&(DATE(2022,12,31)-30))+COUNTIFS('Match History'!AV:AV,B2,'Match History'!A:A,">="&(DATE(2022,12,31)-30))+COUNTIFS('Match History'!AZ:AZ,B2,'Match History'!A:A,">="&(DATE(2022,12,31)-30))+COUNTIFS('Match History'!BD:BD,B2,'Match History'!A:A,">="&(DATE(2022,12,31)-30))+COUNTIFS('Match History'!BH:BH,B2,'Match History'!A:A,">="&(DATE(2022,12,31)-30)) -> 45 | S2: =COUNTIFS('Match History'!B:B,B2,'Match History'!A:A,">="&(DATE(2022,12,31)-365))+COUNTIFS('Match History'!F:F,B2,'Match History'!A:A,">="&(DATE(2022,12,31)-365))+COUNTIFS('Match History'!J:J,B2,'Match History'!A:A,">="&(DATE(2022,12,31)-365))+COUNTIFS('Match History'!N:N,B2,'Match History'!A:A,">="&(DATE(2022,12,31)-365))+COUNTIFS('Match History'!R:R,B2,'Match History'!A:A,">="&(DATE(2022,12,31)-365))+COUNTIFS('Match History'!V:V,B2,'Match History'!A:A,">="&(DATE(2022,12,31)-365))+COUNTIFS('Match History'!Z:Z,B2,'Match History'!A:A,">="&(DATE(2022,12,31)-365))+COUNTIFS('Match History'!AD:AD,B2,'Match History'!A:A,">="&(DATE(2022,12,31)-365))+COUNTIFS('Match History'!AH:AH,B2,'Match History'!A:A,">="&(DATE(2022,12,31)-365))+COUNTIFS('Match History'!AL:AL,B2,'Match History'!A:A,">="&(DATE(2022,12,31)-365))+COUNTIFS('Match History'!AV:AV,B2,'Match History'!A:A,">="&(DATE(2022,12,31)-365))+COUNTIFS('Match History'!AZ:AZ,B2,'Match History'!A:A,">="&(DATE(2022,12,31)-365))+COUNTIFS('Match History'!BD:BD,B2,'Match History'!A:A,">="&(DATE(2022,12,31)-365))+COUNTIFS('Match History'!BH:BH,B2,'Match History'!A:A,">="&(DATE(2022,12,31)-365)) -> 254 | T2: {=IF(F2=0,0,INDEX('Match History'!B:BK,MATCH(N2,'Match History'!A:A,0),MATCH(B2,INDEX('Match History'!B:BK,MATCH(N2,'Match History'!A:A,0),0),0)+3)-INDEX('Match History'!B:BK,MATCH(N2,'Match History'!A:A,0),MATCH(B2,INDEX('Match History'!B:BK,MATCH(N2,'Match History'!A:A,0),0),0)+1))} -> -0.41205241 | U2: =COUNTIFS('Match History'!B:B,B2,'Match History'!A:A,">="&(DATE(2022,12,31)-92)) +COUNTIFS('Match History'!F:F,B2,'Match History'!A:A,">="&(DATE(2022,12,31)-92)) +COUNTIFS('Match History'!J:J,B2,'Match History'!A:A,">="&(DATE(2022,12,31)-92)) +COUNTIFS('Match History'!N:N,B2,'Match History'!A:A,">="&(DATE(2022,12,31)-92)) +COUNTIFS('Match History'!R:R,B2,'Match History'!A:A,">="&(DATE(2022,12,31)-92)) +COUNTIFS('Match History'!V:V,B2,'Match History'!A:A,">="&(DATE(2022,12,31)-92)) +COUNTIFS('Match History'!Z:Z,B2,'Match History'!A:A,">="&(DATE(2022,12,31)-92)) +COUNTIFS('Match History'!AD:AD,B2,'Match History'!A:A,">="&(DATE(2022,12,31)-92)) +COUNTIFS('Match History'!AH:AH,B2,'Match History'!A:A,">="&(DATE(2022,12,31)-92)) +COUNTIFS('Match History'!AL:AL,B2,'Match History'!A:A,">="&(DATE(2022,12,31)-92)) +COUNTIFS('Match History'!AV:AV,B2,'Match History'!A:A,">="&(DATE(2022,12,31)-92)) +COUNTIFS('Match History'!AZ:AZ,B2,'Match History'!A:A,">="&(DATE(2022,12,31)-92)) +COUNTIFS('Match History'!BD:BD,B2,'Match History'!A:A,">="&(DATE(2022,12,31)-92)) +COUNTIFS('Match History'!BH:BH,B2,'Match History'!A:A,">="&(DATE(2022,12,31)-92)) -> 107 | V2: =IF(U2=0,0,(SUMIFS('Match History'!D:D,'Match History'!A:A,">=10/01/2022 00:00",'Match History'!A:A,"<=12/31/2022 23:59",'Match History'!B:B,B2) +SUMIFS('Match History'!H:H,'Match History'!A:A,">=10/01/2022 00:00",'Match History'!A:A,"<=12/31/2022 23:59",'Match History'!F:F,B2) +SUMIFS('Match History'!L:L,'Match History'!A:A,">=10/01/2022 00:00",'Match History'!A:A,"<=12/31/2022 23:59",'Match History'!J:J,B2) +SUMIFS('Match History'!P:P,'Match History'!A:A,">=10/01/2022 00:00",'Match History'!A:A,"<=12/31/2022 23:59",'Match History'!N:N,B2) +SUMIFS('Match History'!T:T,'Match History'!A:A,">=10/01/2022 00:00",'Match History'!A:A,"<=12/31/2022 23:59",'Match History'!R:R,B2) +SUMIFS('Match History'!X:X,'Match History'!A:A,">=10/01/2022 00:00",'Match History'!A:A,"<=12/31/2022 23:59",'Match History'!V:V,B2) +SUMIFS('Match History'!AB:AB,'Match History'!A:A,">=10/01/2022 00:00",'Match History'!A:A,"<=12/31/2022 23:59",'Match History'!Z:Z,B2) +SUMIFS('Match History'!AF:AF,'Match History'!A:A,">=10/01/2022 00:00",'Match History'!A:A,"<=12/31/2022 23:59",'Match History'!AD:AD,B2) +SUMIFS('Match History'!AJ:AJ,'Match History'!A:A,">=10/01/2022 00:00",'Match History'!A:A,"<=12/31/2022 23:59",'Match History'!AH:AH,B2) +SUMIFS('Match History'!AN:AN,'Match History'!A:A,">=10/01/2022 00:00",'Match History'!A:A,"<=12/31/2022 23:59",'Match History'!AL:AL,B2) +SUMIFS('Match History'!AX:AX,'Match History'!A:A,">=10/01/2022 00:00",'Match History'!A:A,"<=12/31/2022 23:59",'Match History'!AV:AV,B2)+SUMIFS('Match History'!BB:BB,'Match History'!A:A,">=10/01/2022 00:00",'Match History'!A:A,"<=12/31/2022 23:59",'Match History'!AZ:AZ,B2) +SUMIFS('Match History'!BF:BF,'Match History'!A:A,">=10/01/2022 00:00",'Match History'!A:A,"<=12/31/2022 23:59",'Match History'!BD:BD,B2) +SUMIFS('Match History'!BJ:BJ,'Match History'!A:A,">=10/01/2022 00:00",'Match History'!A:A,"<=12/31/2022 23:59",'Match History'!BH:BH,B2))/U2) -> 28.700935
A3: Zielakpr0 | B3: zielak | C3: 1190.7306 | D3: =NORMDIST(C3,1000,STDEV($C$2:$C$39)+0.00001,TRUE) -> 0.98954164 | F3: =COUNTIF('Match History'!A:BK,"zielak") -> 918 | G3: PL | H3: - [T]eamForce- | I3: - | J3: 1 | K3: 1 | L3: =AND($N3<>"no war", $N3>=DATE(2022, 12, 31)-30, $M3<>TRUE) -> TRUE | M3: FALSE | N3: {=IF(F3=0, "no war", INDEX('Match History'!A:A, MAX(MAX(('Match History'!B:B=B3)*(ROW('Match History'!B:B))),MAX(('Match History'!F:F=B3)*(ROW('Match History'!F:F))),MAX(('Match History'!J:J=B3)*(ROW('Match History'!J:J))),MAX(('Match History'!N:N=B3)*(ROW('Match History'!N:N))),MAX(('Match History'!R:R=B3)*(ROW('Match History'!R:R))),MAX(('Match History'!V:V=B3)*(ROW('Match History'!V:V))),MAX(('Match History'!Z:Z=B3)*(ROW('Match History'!Z:Z))),MAX(('Match History'!AD:AD=B3)*(ROW('Match History'!AD:AD))),MAX(('Match History'!AH:AH=B3)*(ROW('Match History'!AH:AH))),MAX(('Match History'!AL:AL=B3)*(ROW('Match History'!AL:AL))),MAX(('Match History'!AV:AV=B3)*(ROW('Match History'!AV:AV))),MAX(('Match History'!AZ:AZ=B3)*(ROW('Match History'!AZ:AZ))),MAX(('Match History'!BD:BD=B3)*(ROW('Match History'!BD:BD))),MAX(('Match History'!BH:BH=B3)*(ROW('Match History'!BH:BH)))), 1))} -> 44926.114 | O3: =(SUMIF('Match History'!B:B,B3,'Match History'!D:D)+SUMIF('Match History'!F:F,B3,'Match History'!H:H)+SUMIF('Match History'!J:J,B3,'Match History'!L:L)+SUMIF('Match History'!N:N,B3,'Match History'!P:P)+SUMIF('Match History'!R:R,B3,'Match History'!T:T)+SUMIF('Match History'!V:V,B3,'Match History'!X:X)+SUMIF('Match History'!Z:Z,B3,'Match History'!AB:AB)+SUMIF('Match History'!AD:AD,B3,'Match History'!AF:AF)+SUMIF('Match History'!AH:AH,B3,'Match History'!AJ:AJ)+SUMIF('Match History'!AL:AL,B3,'Match History'!AN:AN)+SUMIF('Match History'!AV:AV,B3,'Match History'!AX:AX)+SUMIF('Match History'!AZ:AZ,B3,'Match History'!BB:BB)+SUMIF('Match History'!BD:BD,B3,'Match History'!BF:BF)+SUMIF('Match History'!BH:BH,B3,'Match History'!BJ:BJ))/IF(F3=0,1,F3) -> 23.253813 | P3: {=MAX(MAX(IF('Match History'!B:B=B3,'Match History'!D:D,)),MAX(IF('Match History'!F:F=B3,'Match History'!H:H,)),MAX(IF('Match History'!J:J=B3,'Match History'!L:L,)),MAX(IF('Match History'!N:N=B3,'Match History'!P:P,)),MAX(IF('Match History'!R:R=B3,'Match History'!T:T,)),MAX(IF('Match History'!V:V=B3,'Match History'!X:X,)),MAX(IF('Match History'!Z:Z=B3,'Match History'!AB:AB,)),MAX(IF('Match History'!AD:AD=B3,'Match History'!AF:AF,)),MAX(IF('Match History'!AH:AH=B3,'Match History'!AJ:AJ,)),MAX(IF('Match History'!AL:AL=B3,'Match History'!AN:AN,)),MAX(IF('Match History'!AV:AV=B3,'Match History'!AX:AX,)),MAX(IF('Match History'!AZ:AZ=B3,'Match History'!BB:BB,)),MAX(IF('Match History'!BD:BD=B3,'Match History'!BF:BF,)),MAX(IF('Match History'!BH:BH=B3,'Match History'!BJ:BJ,)))} -> 62 | Q3: {=IF(F3=0,0,MIN(MIN(IF('Match History'!B:B=B3,'Match History'!D:D,999)),MIN(IF('Match History'!F:F=B3,'Match History'!H:H,999)),MIN(IF('Match History'!J:J=B3,'Match History'!L:L,999)),MIN(IF('Match History'!N:N=B3,'Match History'!P:P,999)),MIN(IF('Match History'!R:R=B3,'Match History'!T:T,999)),MIN(IF('Match History'!V:V=B3,'Match History'!X:X,999)),MIN(IF('Match History'!Z:Z=B3,'Match History'!AB:AB,999)),MIN(IF('Match History'!AD:AD=B3,'Match History'!AF:AF,999)),MIN(IF('Match History'!AH:AH=B3,'Match History'!AJ:AJ,999)),MIN(IF('Match History'!AL:AL=B3,'Match History'!AN:AN,999)),MIN(IF('Match History'!AV:AV=B3,'Match History'!AX:AX,999)),MIN(IF('Match History'!AZ:AZ=B3,'Match History'!BB:BB,999)),MIN(IF('Match History'!BD:BD=B3,'Match History'!BF:BF,999)),MIN(IF('Match History'!BH:BH=B3,'Match History'!BJ:BJ,999))))} -> 5 | R3: =COUNTIFS('Match History'!B:B,B3,'Match History'!A:A,">="&(DATE(2022,12,31)-30))+COUNTIFS('Match History'!F:F,B3,'Match History'!A:A,">="&(DATE(2022,12,31)-30))+COUNTIFS('Match History'!J:J,B3,'Match History'!A:A,">="&(DATE(2022,12,31)-30))+COUNTIFS('Match History'!N:N,B3,'Match History'!A:A,">="&(DATE(2022,12,31)-30))+COUNTIFS('Match History'!R:R,B3,'Match History'!A:A,">="&(DATE(2022,12,31)-30))+COUNTIFS('Match History'!V:V,B3,'Match History'!A:A,">="&(DATE(2022,12,31)-30))+COUNTIFS('Match History'!Z:Z,B3,'Match History'!A:A,">="&(DATE(2022,12,31)-30))+COUNTIFS('Match History'!AD:AD,B3,'Match History'!A:A,">="&(DATE(2022,12,31)-30))+COUNTIFS('Match History'!AH:AH,B3,'Match History'!A:A,">="&(DATE(2022,12,31)-30))+COUNTIFS('Match History'!AL:AL,B3,'Match History'!A:A,">="&(DATE(2022,12,31)-30))+COUNTIFS('Match History'!AV:AV,B3,'Match History'!A:A,">="&(DATE(2022,12,31)-30))+COUNTIFS('Match History'!AZ:AZ,B3,'Match History'!A:A,">="&(DATE(2022,12,31)-30))+COUNTIFS('Match History'!BD:BD,B3,'Match History'!A:A,">="&(DATE(2022,12,31)-30))+COUNTIFS('Match History'!BH:BH,B3,'Match History'!A:A,">="&(DATE(2022,12,31)-30)) -> 58 | S3: =COUNTIFS('Match History'!B:B,B3,'Match History'!A:A,">="&(DATE(2022,12,31)-365))+COUNTIFS('Match History'!F:F,B3,'Match History'!A:A,">="&(DATE(2022,12,31)-365))+COUNTIFS('Match History'!J:J,B3,'Match History'!A:A,">="&(DATE(2022,12,31)-365))+COUNTIFS('Match History'!N:N,B3,'Match History'!A:A,">="&(DATE(2022,12,31)-365))+COUNTIFS('Match History'!R:R,B3,'Match History'!A:A,">="&(DATE(2022,12,31)-365))+COUNTIFS('Match History'!V:V,B3,'Match History'!A:A,">="&(DATE(2022,12,31)-365))+COUNTIFS('Match History'!Z:Z,B3,'Match History'!A:A,">="&(DATE(2022,12,31)-365))+COUNTIFS('Match History'!AD:AD,B3,'Match History'!A:A,">="&(DATE(2022,12,31)-365))+COUNTIFS('Match History'!AH:AH,B3,'Match History'!A:A,">="&(DATE(2022,12,31)-365))+COUNTIFS('Match History'!AL:AL,B3,'Match History'!A:A,">="&(DATE(2022,12,31)-365))+COUNTIFS('Match History'!AV:AV,B3,'Match History'!A:A,">="&(DATE(2022,12,31)-365))+COUNTIFS('Match History'!AZ:AZ,B3,'Match History'!A:A,">="&(DATE(2022,12,31)-365))+COUNTIFS('Match History'!BD:BD,B3,'Match History'!A:A,">="&(DATE(2022,12,31)-365))+COUNTIFS('Match History'!BH:BH,B3,'Match History'!A:A,">="&(DATE(2022,12,31)-365)) -> 434 | T3: {=IF(F3=0,0,INDEX('Match History'!B:BK,MATCH(N3,'Match History'!A:A,0),MATCH(B3,INDEX('Match History'!B:BK,MATCH(N3,'Match History'!A:A,0),0),0)+3)-INDEX('Match History'!B:BK,MATCH(N3,'Match History'!A:A,0),MATCH(B3,INDEX('Match History'!B:BK,MATCH(N3,'Match History'!A:A,0),0),0)+1))} -> -4.6332496 | U3: =COUNTIFS('Match History'!B:B,B3,'Match History'!A:A,">="&(DATE(2022,12,31)-92)) +COUNTIFS('Match History'!F:F,B3,'Match History'!A:A,">="&(DATE(2022,12,31)-92)) +COUNTIFS('Match History'!J:J,B3,'Match History'!A:A,">="&(DATE(2022,12,31)-92)) +COUNTIFS('Match History'!N:N,B3,'Match History'!A:A,">="&(DATE(2022,12,31)-92)) +COUNTIFS('Match History'!R:R,B3,'Match History'!A:A,">="&(DATE(2022,12,31)-92)) +COUNTIFS('Match History'!V:V,B3,'Match History'!A:A,">="&(DATE(2022,12,31)-92)) +COUNTIFS('Match History'!Z:Z,B3,'Match History'!A:A,">="&(DATE(2022,12,31)-92)) +COUNTIFS('Match History'!AD:AD,B3,'Match History'!A:A,">="&(DATE(2022,12,31)-92)) +COUNTIFS('Match History'!AH:AH,B3,'Match History'!A:A,">="&(DATE(2022,12,31)-92)) +COUNTIFS('Match History'!AL:AL,B3,'Match History'!A:A,">="&(DATE(2022,12,31)-92)) +COUNTIFS('Match History'!AV:AV,B3,'Match History'!A:A,">="&(DATE(2022,12,31)-92)) +COUNTIFS('Match History'!AZ:AZ,B3,'Match History'!A:A,">="&(DATE(2022,12,31)-92)) +COUNTIFS('Match History'!BD:BD,B3,'Match History'!A:A,">="&(DATE(2022,12,31)-92)) +COUNTIFS('Match History'!BH:BH,B3,'Match History'!A:A,">="&(DATE(2022,12,31)-92)) -> 143 | V3: =IF(U3=0,0,(SUMIFS('Match History'!D:D,'Match History'!A:A,">=10/01/2022 00:00",'Match History'!A:A,"<=12/31/2022 23:59",'Match History'!B:B,B3) +SUMIFS('Match History'!H:H,'Match History'!A:A,">=10/01/2022 00:00",'Match History'!A:A,"<=12/31/2022 23:59",'Match History'!F:F,B3) +SUMIFS('Match History'!L:L,'Match History'!A:A,">=10/01/2022 00:00",'Match History'!A:A,"<=12/31/2022 23:59",'Match History'!J:J,B3) +SUMIFS('Match History'!P:P,'Match History'!A:A,">=10/01/2022 00:00",'Match History'!A:A,"<=12/31/2022 23:59",'Match History'!N:N,B3) +SUMIFS('Match History'!T:T,'Match History'!A:A,">=10/01/2022 00:00",'Match History'!A:A,"<=12/31/2022 23:59",'Match History'!R:R,B3) +SUMIFS('Match History'!X:X,'Match History'!A:A,">=10/01/2022 00:00",'Match History'!A:A,"<=12/31/2022 23:59",'Match History'!V:V,B3) +SUMIFS('Match History'!AB:AB,'Match History'!A:A,">=10/01/2022 00:00",'Match History'!A:A,"<=12/31/2022 23:59",'Match History'!Z:Z,B3) +SUMIFS('Match History'!AF:AF,'Match History'!A:A,">=10/01/2022 00:00",'Match History'!A:A,"<=12/31/2022 23:59",'Match History'!AD:AD,B3) +SUMIFS('Match History'!AJ:AJ,'Match History'!A:A,">=10/01/2022 00:00",'Match History'!A:A,"<=12/31/2022 23:59",'Match History'!AH:AH,B3) +SUMIFS('Match History'!AN:AN,'Match History'!A:A,">=10/01/2022 00:00",'Match History'!A:A,"<=12/31/2022 23:59",'Match History'!AL:AL,B3) +SUMIFS('Match History'!AX:AX,'Match History'!A:A,">=10/01/2022 00:00",'Match History'!A:A,"<=12/31/2022 23:59",'Match History'!AV:AV,B3)+SUMIFS('Match History'!BB:BB,'Match History'!A:A,">=10/01/2022 00:00",'Match History'!A:A,"<=12/31/2022 23:59",'Match History'!AZ:AZ,B3) +SUMIFS('Match History'!BF:BF,'Match History'!A:A,">=10/01/2022 00:00",'Match History'!A:A,"<=12/31/2022 23:59",'Match History'!BD:BD,B3) +SUMIFS('Match History'!BJ:BJ,'Match History'!A:A,">=10/01/2022 00:00",'Match History'!A:A,"<=12/31/2022 23:59",'Match History'!BH:BH,B3))/U3) -> 24.468531
A4: booGie | B4: boogie | C4: 1178.8854 | D4: =NORMDIST(C4,1000,STDEV(Players!$C$2:$C$39)+0.00001,TRUE) -> 0.98484652 | F4: =COUNTIF('Match History'!A:BK,"boogie") -> 297 | G4: PL | H4: stArs | I4: 1 | L4: =AND($N4<>"no war", $N4>=DATE(2022, 12, 31)-30, $M4<>TRUE) -> TRUE | M4: FALSE | N4: {=IF(F4=0, "no war", INDEX('Match History'!A:A, MAX(MAX(('Match History'!B:B=B4)*(ROW('Match History'!B:B))),MAX(('Match History'!F:F=B4)*(ROW('Match History'!F:F))),MAX(('Match History'!J:J=B4)*(ROW('Match History'!J:J))),MAX(('Match History'!N:N=B4)*(ROW('Match History'!N:N))),MAX(('Match History'!R:R=B4)*(ROW('Match History'!R:R))),MAX(('Match History'!V:V=B4)*(ROW('Match History'!V:V))),MAX(('Match History'!Z:Z=B4)*(ROW('Match History'!Z:Z))),MAX(('Match History'!AD:AD=B4)*(ROW('Match History'!AD:AD))),MAX(('Match History'!AH:AH=B4)*(ROW('Match History'!AH:AH))),MAX(('Match History'!AL:AL=B4)*(ROW('Match History'!AL:AL))),MAX(('Match History'!AV:AV=B4)*(ROW('Match History'!AV:AV))),MAX(('Match History'!AZ:AZ=B4)*(ROW('Match History'!AZ:AZ))),MAX(('Match History'!BD:BD=B4)*(ROW('Match History'!BD:BD))),MAX(('Match History'!BH:BH=B4)*(ROW('Match History'!BH:BH)))), 1))} -> 44926.825 | O4: =(SUMIF('Match History'!B:B,B4,'Match History'!D:D)+SUMIF('Match History'!F:F,B4,'Match History'!H:H)+SUMIF('Match History'!J:J,B4,'Match History'!L:L)+SUMIF('Match History'!N:N,B4,'Match History'!P:P)+SUMIF('Match History'!R:R,B4,'Match History'!T:T)+SUMIF('Match History'!V:V,B4,'Match History'!X:X)+SUMIF('Match History'!Z:Z,B4,'Match History'!AB:AB)+SUMIF('Match History'!AD:AD,B4,'Match History'!AF:AF)+SUMIF('Match History'!AH:AH,B4,'Match History'!AJ:AJ)+SUMIF('Match History'!AL:AL,B4,'Match History'!AN:AN)+SUMIF('Match History'!AV:AV,B4,'Match History'!AX:AX)+SUMIF('Match History'!AZ:AZ,B4,'Match History'!BB:BB)+SUMIF('Match History'!BD:BD,B4,'Match History'!BF:BF)+SUMIF('Match History'!BH:BH,B4,'Match History'!BJ:BJ))/IF(F4=0,1,F4) -> 30.861953 | P4: {=MAX(MAX(IF('Match History'!B:B=B4,'Match History'!D:D,)),MAX(IF('Match History'!F:F=B4,'Match History'!H:H,)),MAX(IF('Match History'!J:J=B4,'Match History'!L:L,)),MAX(IF('Match History'!N:N=B4,'Match History'!P:P,)),MAX(IF('Match History'!R:R=B4,'Match History'!T:T,)),MAX(IF('Match History'!V:V=B4,'Match History'!X:X,)),MAX(IF('Match History'!Z:Z=B4,'Match History'!AB:AB,)),MAX(IF('Match History'!AD:AD=B4,'Match History'!AF:AF,)),MAX(IF('Match History'!AH:AH=B4,'Match History'!AJ:AJ,)),MAX(IF('Match History'!AL:AL=B4,'Match History'!AN:AN,)),MAX(IF('Match History'!AV:AV=B4,'Match History'!AX:AX,)),MAX(IF('Match History'!AZ:AZ=B4,'Match History'!BB:BB,)),MAX(IF('Match History'!BD:BD=B4,'Match History'!BF:BF,)),MAX(IF('Match History'!BH:BH=B4,'Match History'!BJ:BJ,)))} -> 60 | Q4: {=IF(F4=0,0,MIN(MIN(IF('Match History'!B:B=B4,'Match History'!D:D,999)),MIN(IF('Match History'!F:F=B4,'Match History'!H:H,999)),MIN(IF('Match History'!J:J=B4,'Match History'!L:L,999)),MIN(IF('Match History'!N:N=B4,'Match History'!P:P,999)),MIN(IF('Match History'!R:R=B4,'Match History'!T:T,999)),MIN(IF('Match History'!V:V=B4,'Match History'!X:X,999)),MIN(IF('Match History'!Z:Z=B4,'Match History'!AB:AB,999)),MIN(IF('Match History'!AD:AD=B4,'Match History'!AF:AF,999)),MIN(IF('Match History'!AH:AH=B4,'Match History'!AJ:AJ,999)),MIN(IF('Match History'!AL:AL=B4,'Match History'!AN:AN,999)),MIN(IF('Match History'!AV:AV=B4,'Match History'!AX:AX,999)),MIN(IF('Match History'!AZ:AZ=B4,'Match History'!BB:BB,999)),MIN(IF('Match History'!BD:BD=B4,'Match History'!BF:BF,999)),MIN(IF('Match History'!BH:BH=B4,'Match History'!BJ:BJ,999))))} -> 8 | R4: =COUNTIFS('Match History'!B:B,B4,'Match History'!A:A,">="&(DATE(2022,12,31)-30))+COUNTIFS('Match History'!F:F,B4,'Match History'!A:A,">="&(DATE(2022,12,31)-30))+COUNTIFS('Match History'!J:J,B4,'Match History'!A:A,">="&(DATE(2022,12,31)-30))+COUNTIFS('Match History'!N:N,B4,'Match History'!A:A,">="&(DATE(2022,12,31)-30))+COUNTIFS('Match History'!R:R,B4,'Match History'!A:A,">="&(DATE(2022,12,31)-30))+COUNTIFS('Match History'!V:V,B4,'Match History'!A:A,">="&(DATE(2022,12,31)-30))+COUNTIFS('Match History'!Z:Z,B4,'Match History'!A:A,">="&(DATE(2022,12,31)-30))+COUNTIFS('Match History'!AD:AD,B4,'Match History'!A:A,">="&(DATE(2022,12,31)-30))+COUNTIFS('Match History'!AH:AH,B4,'Match History'!A:A,">="&(DATE(2022,12,31)-30))+COUNTIFS('Match History'!AL:AL,B4,'Match History'!A:A,">="&(DATE(2022,12,31)-30))+COUNTIFS('Match History'!AV:AV,B4,'Match History'!A:A,">="&(DATE(2022,12,31)-30))+COUNTIFS('Match History'!AZ:AZ,B4,'Match History'!A:A,">="&(DATE(2022,12,31)-30))+COUNTIFS('Match History'!BD:BD,B4,'Match History'!A:A,">="&(DATE(2022,12,31)-30))+COUNTIFS('Match History'!BH:BH,B4,'Match History'!A:A,">="&(DATE(2022,12,31)-30)) -> 18 | S4: =COUNTIFS('Match History'!B:B,B4,'Match History'!A:A,">="&(DATE(2022,12,31)-365))+COUNTIFS('Match History'!F:F,B4,'Match History'!A:A,">="&(DATE(2022,12,31)-365))+COUNTIFS('Match History'!J:J,B4,'Match History'!A:A,">="&(DATE(2022,12,31)-365))+COUNTIFS('Match History'!N:N,B4,'Match History'!A:A,">="&(DATE(2022,12,31)-365))+COUNTIFS('Match History'!R:R,B4,'Match History'!A:A,">="&(DATE(2022,12,31)-365))+COUNTIFS('Match History'!V:V,B4,'Match History'!A:A,">="&(DATE(2022,12,31)-365))+COUNTIFS('Match History'!Z:Z,B4,'Match History'!A:A,">="&(DATE(2022,12,31)-365))+COUNTIFS('Match History'!AD:AD,B4,'Match History'!A:A,">="&(DATE(2022,12,31)-365))+COUNTIFS('Match History'!AH:AH,B4,'Match History'!A:A,">="&(DATE(2022,12,31)-365))+COUNTIFS('Match History'!AL:AL,B4,'Match History'!A:A,">="&(DATE(2022,12,31)-365))+COUNTIFS('Match History'!AV:AV,B4,'Match History'!A:A,">="&(DATE(2022,12,31)-365))+COUNTIFS('Match History'!AZ:AZ,B4,'Match History'!A:A,">="&(DATE(2022,12,31)-365))+COUNTIFS('Match History'!BD:BD,B4,'Match History'!A:A,">="&(DATE(2022,12,31)-365))+COUNTIFS('Match History'!BH:BH,B4,'Match History'!A:A,">="&(DATE(2022,12,31)-365)) -> 82 | T4: {=IF(F4=0,0,INDEX('Match History'!B:BK,MATCH(N4,'Match History'!A:A,0),MATCH(B4,INDEX('Match History'!B:BK,MATCH(N4,'Match History'!A:A,0),0),0)+3)-INDEX('Match History'!B:BK,MATCH(N4,'Match History'!A:A,0),MATCH(B4,INDEX('Match History'!B:BK,MATCH(N4,'Match History'!A:A,0),0),0)+1))} -> 1.3233096 | U4: =COUNTIFS('Match History'!B:B,B4,'Match History'!A:A,">="&(DATE(2022,12,31)-92)) +COUNTIFS('Match History'!F:F,B4,'Match History'!A:A,">="&(DATE(2022,12,31)-92)) +COUNTIFS('Match History'!J:J,B4,'Match History'!A:A,">="&(DATE(2022,12,31)-92)) +COUNTIFS('Match History'!N:N,B4,'Match History'!A:A,">="&(DATE(2022,12,31)-92)) +COUNTIFS('Match History'!R:R,B4,'Match History'!A:A,">="&(DATE(2022,12,31)-92)) +COUNTIFS('Match History'!V:V,B4,'Match History'!A:A,">="&(DATE(2022,12,31)-92)) +COUNTIFS('Match History'!Z:Z,B4,'Match History'!A:A,">="&(DATE(2022,12,31)-92)) +COUNTIFS('Match History'!AD:AD,B4,'Match History'!A:A,">="&(DATE(2022,12,31)-92)) +COUNTIFS('Match History'!AH:AH,B4,'Match History'!A:A,">="&(DATE(2022,12,31)-92)) +COUNTIFS('Match History'!AL:AL,B4,'Match History'!A:A,">="&(DATE(2022,12,31)-92)) +COUNTIFS('Match History'!AV:AV,B4,'Match History'!A:A,">="&(DATE(2022,12,31)-92)) +COUNTIFS('Match History'!AZ:AZ,B4,'Match History'!A:A,">="&(DATE(2022,12,31)-92)) +COUNTIFS('Match History'!BD:BD,B4,'Match History'!A:A,">="&(DATE(2022,12,31)-92)) +COUNTIFS('Match History'!BH:BH,B4,'Match History'!A:A,">="&(DATE(2022,12,31)-92)) -> 18 | V4: =IF(U4=0,0,(SUMIFS('Match History'!D:D,'Match History'!A:A,">=10/01/2022 00:00",'Match History'!A:A,"<=12/31/2022 23:59",'Match History'!B:B,B4) +SUMIFS('Match History'!H:H,'Match History'!A:A,">=10/01/2022 00:00",'Match History'!A:A,"<=12/31/2022 23:59",'Match History'!F:F,B4) +SUMIFS('Match History'!L:L,'Match History'!A:A,">=10/01/2022 00:00",'Match History'!A:A,"<=12/31/2022 23:59",'Match History'!J:J,B4) +SUMIFS('Match History'!P:P,'Match History'!A:A,">=10/01/2022 00:00",'Match History'!A:A,"<=12/31/2022 23:59",'Match History'!N:N,B4) +SUMIFS('Match History'!T:T,'Match History'!A:A,">=10/01/2022 00:00",'Match History'!A:A,"<=12/31/2022 23:59",'Match History'!R:R,B4) +SUMIFS('Match History'!X:X,'Match History'!A:A,">=10/01/2022 00:00",'Match History'!A:A,"<=12/31/2022 23:59",'Match History'!V:V,B4) +SUMIFS('Match History'!AB:AB,'Match History'!A:A,">=10/01/2022 00:00",'Match History'!A:A,"<=12/31/2022 23:59",'Match History'!Z:Z,B4) +SUMIFS('Match History'!AF:AF,'Match History'!A:A,">=10/01/2022 00:00",'Match History'!A:A,"<=12/31/2022 23:59",'Match History'!AD:AD,B4) +SUMIFS('Match History'!AJ:AJ,'Match History'!A:A,">=10/01/2022 00:00",'Match History'!A:A,"<=12/31/2022 23:59",'Match History'!AH:AH,B4) +SUMIFS('Match History'!AN:AN,'Match History'!A:A,">=10/01/2022 00:00",'Match History'!A:A,"<=12/31/2022 23:59",'Match History'!AL:AL,B4) +SUMIFS('Match History'!AX:AX,'Match History'!A:A,">=10/01/2022 00:00",'Match History'!A:A,"<=12/31/2022 23:59",'Match History'!AV:AV,B4)+SUMIFS('Match History'!BB:BB,'Match History'!A:A,">=10/01/2022 00:00",'Match History'!A:A,"<=12/31/2022 23:59",'Match History'!AZ:AZ,B4) +SUMIFS('Match History'!BF:BF,'Match History'!A:A,">=10/01/2022 00:00",'Match History'!A:A,"<=12/31/2022 23:59",'Match History'!BD:BD,B4) +SUMIFS('Match History'!BJ:BJ,'Match History'!A:A,">=10/01/2022 00:00",'Match History'!A:A,"<=12/31/2022 23:59",'Match History'!BH:BH,B4))/U4) -> 33.833333
A5: SzyCha | B5: szycha | C5: 1090.9375 | D5: =NORMDIST(C5,1000,STDEV($C$2:$C$39)+0.00001,TRUE) -> 0.86457937 | F5: =COUNTIF('Match History'!A:BK,"szycha") -> 374 | G5: PL | H5: stArs | I5: - | K5: 1 | L5: =AND($N5<>"no war", $N5>=DATE(2022, 12, 31)-30, $M5<>TRUE) -> TRUE | M5: FALSE | N5: {=IF(F5=0, "no war", INDEX('Match History'!A:A, MAX(MAX(('Match History'!B:B=B5)*(ROW('Match History'!B:B))),MAX(('Match History'!F:F=B5)*(ROW('Match History'!F:F))),MAX(('Match History'!J:J=B5)*(ROW('Match History'!J:J))),MAX(('Match History'!N:N=B5)*(ROW('Match History'!N:N))),MAX(('Match History'!R:R=B5)*(ROW('Match History'!R:R))),MAX(('Match History'!V:V=B5)*(ROW('Match History'!V:V))),MAX(('Match History'!Z:Z=B5)*(ROW('Match History'!Z:Z))),MAX(('Match History'!AD:AD=B5)*(ROW('Match History'!AD:AD))),MAX(('Match History'!AH:AH=B5)*(ROW('Match History'!AH:AH))),MAX(('Match History'!AL:AL=B5)*(ROW('Match History'!AL:AL))),MAX(('Match History'!AV:AV=B5)*(ROW('Match History'!AV:AV))),MAX(('Match History'!AZ:AZ=B5)*(ROW('Match History'!AZ:AZ))),MAX(('Match History'!BD:BD=B5)*(ROW('Match History'!BD:BD))),MAX(('Match History'!BH:BH=B5)*(ROW('Match History'!BH:BH)))), 1))} -> 44925.089 | O5: =(SUMIF('Match History'!B:B,B5,'Match History'!D:D)+SUMIF('Match History'!F:F,B5,'Match History'!H:H)+SUMIF('Match History'!J:J,B5,'Match History'!L:L)+SUMIF('Match History'!N:N,B5,'Match History'!P:P)+SUMIF('Match History'!R:R,B5,'Match History'!T:T)+SUMIF('Match History'!V:V,B5,'Match History'!X:X)+SUMIF('Match History'!Z:Z,B5,'Match History'!AB:AB)+SUMIF('Match History'!AD:AD,B5,'Match History'!AF:AF)+SUMIF('Match History'!AH:AH,B5,'Match History'!AJ:AJ)+SUMIF('Match History'!AL:AL,B5,'Match History'!AN:AN)+SUMIF('Match History'!AV:AV,B5,'Match History'!AX:AX)+SUMIF('Match History'!AZ:AZ,B5,'Match History'!BB:BB)+SUMIF('Match History'!BD:BD,B5,'Match History'!BF:BF)+SUMIF('Match History'!BH:BH,B5,'Match History'!BJ:BJ))/IF(F5=0,1,F5) -> 20.120321 | P5: {=MAX(MAX(IF('Match History'!B:B=B5,'Match History'!D:D,)),MAX(IF('Match History'!F:F=B5,'Match History'!H:H,)),MAX(IF('Match History'!J:J=B5,'Match History'!L:L,)),MAX(IF('Match History'!N:N=B5,'Match History'!P:P,)),MAX(IF('Match History'!R:R=B5,'Match History'!T:T,)),MAX(IF('Match History'!V:V=B5,'Match History'!X:X,)),MAX(IF('Match History'!Z:Z=B5,'Match History'!AB:AB,)),MAX(IF('Match History'!AD:AD=B5,'Match History'!AF:AF,)),MAX(IF('Match History'!AH:AH=B5,'Match History'!AJ:AJ,)),MAX(IF('Match History'!AL:AL=B5,'Match History'!AN:AN,)),MAX(IF('Match History'!AV:AV=B5,'Match History'!AX:AX,)),MAX(IF('Match History'!AZ:AZ=B5,'Match History'!BB:BB,)),MAX(IF('Match History'!BD:BD=B5,'Match History'!BF:BF,)),MAX(IF('Match History'!BH:BH=B5,'Match History'!BJ:BJ,)))} -> 57 | Q5: {=IF(F5=0,0,MIN(MIN(IF('Match History'!B:B=B5,'Match History'!D:D,999)),MIN(IF('Match History'!F:F=B5,'Match History'!H:H,999)),MIN(IF('Match History'!J:J=B5,'Match History'!L:L,999)),MIN(IF('Match History'!N:N=B5,'Match History'!P:P,999)),MIN(IF('Match History'!R:R=B5,'Match History'!T:T,999)),MIN(IF('Match History'!V:V=B5,'Match History'!X:X,999)),MIN(IF('Match History'!Z:Z=B5,'Match History'!AB:AB,999)),MIN(IF('Match History'!AD:AD=B5,'Match History'!AF:AF,999)),MIN(IF('Match History'!AH:AH=B5,'Match History'!AJ:AJ,999)),MIN(IF('Match History'!AL:AL=B5,'Match History'!AN:AN,999)),MIN(IF('Match History'!AV:AV=B5,'Match History'!AX:AX,999)),MIN(IF('Match History'!AZ:AZ=B5,'Match History'!BB:BB,999)),MIN(IF('Match History'!BD:BD=B5,'Match History'!BF:BF,999)),MIN(IF('Match History'!BH:BH=B5,'Match History'!BJ:BJ,999))))} -> 2 | R5: =COUNTIFS('Match History'!B:B,B5,'Match History'!A:A,">="&(DATE(2022,12,31)-30))+COUNTIFS('Match History'!F:F,B5,'Match History'!A:A,">="&(DATE(2022,12,31)-30))+COUNTIFS('Match History'!J:J,B5,'Match History'!A:A,">="&(DATE(2022,12,31)-30))+COUNTIFS('Match History'!N:N,B5,'Match History'!A:A,">="&(DATE(2022,12,31)-30))+COUNTIFS('Match History'!R:R,B5,'Match History'!A:A,">="&(DATE(2022,12,31)-30))+COUNTIFS('Match History'!V:V,B5,'Match History'!A:A,">="&(DATE(2022,12,31)-30))+COUNTIFS('Match History'!Z:Z,B5,'Match History'!A:A,">="&(DATE(2022,12,31)-30))+COUNTIFS('Match History'!AD:AD,B5,'Match History'!A:A,">="&(DATE(2022,12,31)-30))+COUNTIFS('Match History'!AH:AH,B5,'Match History'!A:A,">="&(DATE(2022,12,31)-30))+COUNTIFS('Match History'!AL:AL,B5,'Match History'!A:A,">="&(DATE(2022,12,31)-30))+COUNTIFS('Match History'!AV:AV,B5,'Match History'!A:A,">="&(DATE(2022,12,31)-30))+COUNTIFS('Match History'!AZ:AZ,B5,'Match History'!A:A,">="&(DATE(2022,12,31)-30))+COUNTIFS('Match History'!BD:BD,B5,'Match History'!A:A,">="&(DATE(2022,12,31)-30))+COUNTIFS('Match History'!BH:BH,B5,'Match History'!A:A,">="&(DATE(2022,12,31)-30)) -> 25 | S5: =COUNTIFS('Match History'!B:B,B5,'Match History'!A:A,">="&(DATE(2022,12,31)-365))+COUNTIFS('Match History'!F:F,B5,'Match History'!A:A,">="&(DATE(2022,12,31)-365))+COUNTIFS('Match History'!J:J,B5,'Match History'!A:A,">="&(DATE(2022,12,31)-365))+COUNTIFS('Match History'!N:N,B5,'Match History'!A:A,">="&(DATE(2022,12,31)-365))+COUNTIFS('Match History'!R:R,B5,'Match History'!A:A,">="&(DATE(2022,12,31)-365))+COUNTIFS('Match History'!V:V,B5,'Match History'!A:A,">="&(DATE(2022,12,31)-365))+COUNTIFS('Match History'!Z:Z,B5,'Match History'!A:A,">="&(DATE(2022,12,31)-365))+COUNTIFS('Match History'!AD:AD,B5,'Match History'!A:A,">="&(DATE(2022,12,31)-365))+COUNTIFS('Match History'!AH:AH,B5,'Match History'!A:A,">="&(DATE(2022,12,31)-365))+COUNTIFS('Match History'!AL:AL,B5,'Match History'!A:A,">="&(DATE(2022,12,31)-365))+COUNTIFS('Match History'!AV:AV,B5,'Match History'!A:A,">="&(DATE(2022,12,31)-365))+COUNTIFS('Match History'!AZ:AZ,B5,'Match History'!A:A,">="&(DATE(2022,12,31)-365))+COUNTIFS('Match History'!BD:BD,B5,'Match History'!A:A,">="&(DATE(2022,12,31)-365))+COUNTIFS('Match History'!BH:BH,B5,'Match History'!A:A,">="&(DATE(2022,12,31)-365)) -> 228 | T5: {=IF(F5=0,0,INDEX('Match History'!B:BK,MATCH(N5,'Match History'!A:A,0),MATCH(B5,INDEX('Match History'!B:BK,MATCH(N5,'Match History'!A:A,0),0),0)+3)-INDEX('Match History'!B:BK,MATCH(N5,'Match History'!A:A,0),MATCH(B5,INDEX('Match History'!B:BK,MATCH(N5,'Match History'!A:A,0),0),0)+1))} -> 2.8892584 | U5: =COUNTIFS('Match History'!B:B,B5,'Match History'!A:A,">="&(DATE(2022,12,31)-92)) +COUNTIFS('Match History'!F:F,B5,'Match History'!A:A,">="&(DATE(2022,12,31)-92)) +COUNTIFS('Match History'!J:J,B5,'Match History'!A:A,">="&(DATE(2022,12,31)-92)) +COUNTIFS('Match History'!N:N,B5,'Match History'!A:A,">="&(DATE(2022,12,31)-92)) +COUNTIFS('Match History'!R:R,B5,'Match History'!A:A,">="&(DATE(2022,12,31)-92)) +COUNTIFS('Match History'!V:V,B5,'Match History'!A:A,">="&(DATE(2022,12,31)-92)) +COUNTIFS('Match History'!Z:Z,B5,'Match History'!A:A,">="&(DATE(2022,12,31)-92)) +COUNTIFS('Match History'!AD:AD,B5,'Match History'!A:A,">="&(DATE(2022,12,31)-92)) +COUNTIFS('Match History'!AH:AH,B5,'Match History'!A:A,">="&(DATE(2022,12,31)-92)) +COUNTIFS('Match History'!AL:AL,B5,'Match History'!A:A,">="&(DATE(2022,12,31)-92)) +COUNTIFS('Match History'!AV:AV,B5,'Match History'!A:A,">="&(DATE(2022,12,31)-92)) +COUNTIFS('Match History'!AZ:AZ,B5,'Match History'!A:A,">="&(DATE(2022,12,31)-92)) +COUNTIFS('Match History'!BD:BD,B5,'Match History'!A:A,">="&(DATE(2022,12,31)-92)) +COUNTIFS('Match History'!BH:BH,B5,'Match History'!A:A,">="&(DATE(2022,12,31)-92)) -> 71 | V5: =IF(U5=0,0,(SUMIFS('Match History'!D:D,'Match History'!A:A,">=10/01/2022 00:00",'Match History'!A:A,"<=12/31/2022 23:59",'Match History'!B:B,B5) +SUMIFS('Match History'!H:H,'Match History'!A:A,">=10/01/2022 00:00",'Match History'!A:A,"<=12/31/2022 23:59",'Match History'!F:F,B5) +SUMIFS('Match History'!L:L,'Match History'!A:A,">=10/01/2022 00:00",'Match History'!A:A,"<=12/31/2022 23:59",'Match History'!J:J,B5) +SUMIFS('Match History'!P:P,'Match History'!A:A,">=10/01/2022 00:00",'Match History'!A:A,"<=12/31/2022 23:59",'Match History'!N:N,B5) +SUMIFS('Match History'!T:T,'Match History'!A:A,">=10/01/2022 00:00",'Match History'!A:A,"<=12/31/2022 23:59",'Match History'!R:R,B5) +SUMIFS('Match History'!X:X,'Match History'!A:A,">=10/01/2022 00:00",'Match History'!A:A,"<=12/31/2022 23:59",'Match History'!V:V,B5) +SUMIFS('Match History'!AB:AB,'Match History'!A:A,">=10/01/2022 00:00",'Match History'!A:A,"<=12/31/2022 23:59",'Match History'!Z:Z,B5) +SUMIFS('Match History'!AF:AF,'Match History'!A:A,">=10/01/2022 00:00",'Match History'!A:A,"<=12/31/2022 23:59",'Match History'!AD:AD,B5) +SUMIFS('Match History'!AJ:AJ,'Match History'!A:A,">=10/01/2022 00:00",'Match History'!A:A,"<=12/31/2022 23:59",'Match History'!AH:AH,B5) +SUMIFS('Match History'!AN:AN,'Match History'!A:A,">=10/01/2022 00:00",'Match History'!A:A,"<=12/31/2022 23:59",'Match History'!AL:AL,B5) +SUMIFS('Match History'!AX:AX,'Match History'!A:A,">=10/01/2022 00:00",'Match History'!A:A,"<=12/31/2022 23:59",'Match History'!AV:AV,B5)+SUMIFS('Match History'!BB:BB,'Match History'!A:A,">=10/01/2022 00:00",'Match History'!A:A,"<=12/31/2022 23:59",'Match History'!AZ:AZ,B5) +SUMIFS('Match History'!BF:BF,'Match History'!A:A,">=10/01/2022 00:00",'Match History'!A:A,"<=12/31/2022 23:59",'Match History'!BD:BD,B5) +SUMIFS('Match History'!BJ:BJ,'Match History'!A:A,">=10/01/2022 00:00",'Match History'!A:A,"<=12/31/2022 23:59",'Match History'!BH:BH,B5))/U5) -> 22.309859
A6: evoltnz | B6: evoltnz | C6: 1058.2003 | D6: =NORMDIST(C6,1000,STDEV(Players!$C$2:$C$39)+0.00001,TRUE) -> 0.75950946 | F6: =COUNTIF('Match History'!A:BK,"evoltnz") -> 142 | G6: GR | H6: - | I6: - | L6: =AND($N6<>"no war", $N6>=DATE(2022, 12, 31)-30, $M6<>TRUE) -> TRUE | M6: FALSE | N6: {=IF(F6=0, "no war", INDEX('Match History'!A:A, MAX(MAX(('Match History'!B:B=B6)*(ROW('Match History'!B:B))),MAX(('Match History'!F:F=B6)*(ROW('Match History'!F:F))),MAX(('Match History'!J:J=B6)*(ROW('Match History'!J:J))),MAX(('Match History'!N:N=B6)*(ROW('Match History'!N:N))),MAX(('Match History'!R:R=B6)*(ROW('Match History'!R:R))),MAX(('Match History'!V:V=B6)*(ROW('Match History'!V:V))),MAX(('Match History'!Z:Z=B6)*(ROW('Match History'!Z:Z))),MAX(('Match History'!AD:AD=B6)*(ROW('Match History'!AD:AD))),MAX(('Match History'!AH:AH=B6)*(ROW('Match History'!AH:AH))),MAX(('Match History'!AL:AL=B6)*(ROW('Match History'!AL:AL))),MAX(('Match History'!AV:AV=B6)*(ROW('Match History'!AV:AV))),MAX(('Match History'!AZ:AZ=B6)*(ROW('Match History'!AZ:AZ))),MAX(('Match History'!BD:BD=B6)*(ROW('Match History'!BD:BD))),MAX(('Match History'!BH:BH=B6)*(ROW('Match History'!BH:BH)))), 1))} -> 44924.073 | O6: =(SUMIF('Match History'!B:B,B6,'Match History'!D:D)+SUMIF('Match History'!F:F,B6,'Match History'!H:H)+SUMIF('Match History'!J:J,B6,'Match History'!L:L)+SUMIF('Match History'!N:N,B6,'Match History'!P:P)+SUMIF('Match History'!R:R,B6,'Match History'!T:T)+SUMIF('Match History'!V:V,B6,'Match History'!X:X)+SUMIF('Match History'!Z:Z,B6,'Match History'!AB:AB)+SUMIF('Match History'!AD:AD,B6,'Match History'!AF:AF)+SUMIF('Match History'!AH:AH,B6,'Match History'!AJ:AJ)+SUMIF('Match History'!AL:AL,B6,'Match History'!AN:AN)+SUMIF('Match History'!AV:AV,B6,'Match History'!AX:AX)+SUMIF('Match History'!AZ:AZ,B6,'Match History'!BB:BB)+SUMIF('Match History'!BD:BD,B6,'Match History'!BF:BF)+SUMIF('Match History'!BH:BH,B6,'Match History'!BJ:BJ))/IF(F6=0,1,F6) -> 31.528169 | P6: {=MAX(MAX(IF('Match History'!B:B=B6,'Match History'!D:D,)),MAX(IF('Match History'!F:F=B6,'Match History'!H:H,)),MAX(IF('Match History'!J:J=B6,'Match History'!L:L,)),MAX(IF('Match History'!N:N=B6,'Match History'!P:P,)),MAX(IF('Match History'!R:R=B6,'Match History'!T:T,)),MAX(IF('Match History'!V:V=B6,'Match History'!X:X,)),MAX(IF('Match History'!Z:Z=B6,'Match History'!AB:AB,)),MAX(IF('Match History'!AD:AD=B6,'Match History'!AF:AF,)),MAX(IF('Match History'!AH:AH=B6,'Match History'!AJ:AJ,)),MAX(IF('Match History'!AL:AL=B6,'Match History'!AN:AN,)),MAX(IF('Match History'!AV:AV=B6,'Match History'!AX:AX,)),MAX(IF('Match History'!AZ:AZ=B6,'Match History'!BB:BB,)),MAX(IF('Match History'!BD:BD=B6,'Match History'!BF:BF,)),MAX(IF('Match History'!BH:BH=B6,'Match History'!BJ:BJ,)))} -> 76 | Q6: {=IF(F6=0,0,MIN(MIN(IF('Match History'!B:B=B6,'Match History'!D:D,999)),MIN(IF('Match History'!F:F=B6,'Match History'!H:H,999)),MIN(IF('Match History'!J:J=B6,'Match History'!L:L,999)),MIN(IF('Match History'!N:N=B6,'Match History'!P:P,999)),MIN(IF('Match History'!R:R=B6,'Match History'!T:T,999)),MIN(IF('Match History'!V:V=B6,'Match History'!X:X,999)),MIN(IF('Match History'!Z:Z=B6,'Match History'!AB:AB,999)),MIN(IF('Match History'!AD:AD=B6,'Match History'!AF:AF,999)),MIN(IF('Match History'!AH:AH=B6,'Match History'!AJ:AJ,999)),MIN(IF('Match History'!AL:AL=B6,'Match History'!AN:AN,999)),MIN(IF('Match History'!AV:AV=B6,'Match History'!AX:AX,999)),MIN(IF('Match History'!AZ:AZ=B6,'Match History'!BB:BB,999)),MIN(IF('Match History'!BD:BD=B6,'Match History'!BF:BF,999)),MIN(IF('Match History'!BH:BH=B6,'Match History'!BJ:BJ,999))))} -> 12 | R6: =COUNTIFS('Match History'!B:B,B6,'Match History'!A:A,">="&(DATE(2022,12,31)-30))+COUNTIFS('Match History'!F:F,B6,'Match History'!A:A,">="&(DATE(2022,12,31)-30))+COUNTIFS('Match History'!J:J,B6,'Match History'!A:A,">="&(DATE(2022,12,31)-30))+COUNTIFS('Match History'!N:N,B6,'Match History'!A:A,">="&(DATE(2022,12,31)-30))+COUNTIFS('Match History'!R:R,B6,'Match History'!A:A,">="&(DATE(2022,12,31)-30))+COUNTIFS('Match History'!V:V,B6,'Match History'!A:A,">="&(DATE(2022,12,31)-30))+COUNTIFS('Match History'!Z:Z,B6,'Match History'!A:A,">="&(DATE(2022,12,31)-30))+COUNTIFS('Match History'!AD:AD,B6,'Match History'!A:A,">="&(DATE(2022,12,31)-30))+COUNTIFS('Match History'!AH:AH,B6,'Match History'!A:A,">="&(DATE(2022,12,31)-30))+COUNTIFS('Match History'!AL:AL,B6,'Match History'!A:A,">="&(DATE(2022,12,31)-30))+COUNTIFS('Match History'!AV:AV,B6,'Match History'!A:A,">="&(DATE(2022,12,31)-30))+COUNTIFS('Match History'!AZ:AZ,B6,'Match History'!A:A,">="&(DATE(2022,12,31)-30))+COUNTIFS('Match History'!BD:BD,B6,'Match History'!A:A,">="&(DATE(2022,12,31)-30))+COUNTIFS('Match History'!BH:BH,B6,'Match History'!A:A,">="&(DATE(2022,12,31)-30)) -> 7 | S6: =COUNTIFS('Match History'!B:B,B6,'Match History'!A:A,">="&(DATE(2022,12,31)-365))+COUNTIFS('Match History'!F:F,B6,'Match History'!A:A,">="&(DATE(2022,12,31)-365))+COUNTIFS('Match History'!J:J,B6,'Match History'!A:A,">="&(DATE(2022,12,31)-365))+COUNTIFS('Match History'!N:N,B6,'Match History'!A:A,">="&(DATE(2022,12,31)-365))+COUNTIFS('Match History'!R:R,B6,'Match History'!A:A,">="&(DATE(2022,12,31)-365))+COUNTIFS('Match History'!V:V,B6,'Match History'!A:A,">="&(DATE(2022,12,31)-365))+COUNTIFS('Match History'!Z:Z,B6,'Match History'!A:A,">="&(DATE(2022,12,31)-365))+COUNTIFS('Match History'!AD:AD,B6,'Match History'!A:A,">="&(DATE(2022,12,31)-365))+COUNTIFS('Match History'!AH:AH,B6,'Match History'!A:A,">="&(DATE(2022,12,31)-365))+COUNTIFS('Match History'!AL:AL,B6,'Match History'!A:A,">="&(DATE(2022,12,31)-365))+COUNTIFS('Match History'!AV:AV,B6,'Match History'!A:A,">="&(DATE(2022,12,31)-365))+COUNTIFS('Match History'!AZ:AZ,B6,'Match History'!A:A,">="&(DATE(2022,12,31)-365))+COUNTIFS('Match History'!BD:BD,B6,'Match History'!A:A,">="&(DATE(2022,12,31)-365))+COUNTIFS('Match History'!BH:BH,B6,'Match History'!A:A,">="&(DATE(2022,12,31)-365)) -> 12 | T6: {=IF(F6=0,0,INDEX('Match History'!B:BK,MATCH(N6,'Match History'!A:A,0),MATCH(B6,INDEX('Match History'!B:BK,MATCH(N6,'Match History'!A:A,0),0),0)+3)-INDEX('Match History'!B:BK,MATCH(N6,'Match History'!A:A,0),MATCH(B6,INDEX('Match History'!B:BK,MATCH(N6,'Match History'!A:A,0),0),0)+1))} -> 11.324994 | U6: =COUNTIFS('Match History'!B:B,B6,'Match History'!A:A,">="&(DATE(2022,12,31)-92)) +COUNTIFS('Match History'!F:F,B6,'Match History'!A:A,">="&(DATE(2022,12,31)-92)) +COUNTIFS('Match History'!J:J,B6,'Match History'!A:A,">="&(DATE(2022,12,31)-92)) +COUNTIFS('Match History'!N:N,B6,'Match History'!A:A,">="&(DATE(2022,12,31)-92)) +COUNTIFS('Match History'!R:R,B6,'Match History'!A:A,">="&(DATE(2022,12,31)-92)) +COUNTIFS('Match History'!V:V,B6,'Match History'!A:A,">="&(DATE(2022,12,31)-92)) +COUNTIFS('Match History'!Z:Z,B6,'Match History'!A:A,">="&(DATE(2022,12,31)-92)) +COUNTIFS('Match History'!AD:AD,B6,'Match History'!A:A,">="&(DATE(2022,12,31)-92)) +COUNTIFS('Match History'!AH:AH,B6,'Match History'!A:A,">="&(DATE(2022,12,31)-92)) +COUNTIFS('Match History'!AL:AL,B6,'Match History'!A:A,">="&(DATE(2022,12,31)-92)) +COUNTIFS('Match History'!AV:AV,B6,'Match History'!A:A,">="&(DATE(2022,12,31)-92)) +COUNTIFS('Match History'!AZ:AZ,B6,'Match History'!A:A,">="&(DATE(2022,12,31)-92)) +COUNTIFS('Match History'!BD:BD,B6,'Match History'!A:A,">="&(DATE(2022,12,31)-92)) +COUNTIFS('Match History'!BH:BH,B6,'Match History'!A:A,">="&(DATE(2022,12,31)-92)) -> 7 | V6: =IF(U6=0,0,(SUMIFS('Match History'!D:D,'Match History'!A:A,">=10/01/2022 00:00",'Match History'!A:A,"<=12/31/2022 23:59",'Match History'!B:B,B6) +SUMIFS('Match History'!H:H,'Match History'!A:A,">=10/01/2022 00:00",'Match History'!A:A,"<=12/31/2022 23:59",'Match History'!F:F,B6) +SUMIFS('Match History'!L:L,'Match History'!A:A,">=10/01/2022 00:00",'Match History'!A:A,"<=12/31/2022 23:59",'Match History'!J:J,B6) +SUMIFS('Match History'!P:P,'Match History'!A:A,">=10/01/2022 00:00",'Match History'!A:A,"<=12/31/2022 23:59",'Match History'!N:N,B6) +SUMIFS('Match History'!T:T,'Match History'!A:A,">=10/01/2022 00:00",'Match History'!A:A,"<=12/31/2022 23:59",'Match History'!R:R,B6) +SUMIFS('Match History'!X:X,'Match History'!A:A,">=10/01/2022 00:00",'Match History'!A:A,"<=12/31/2022 23:59",'Match History'!V:V,B6) +SUMIFS('Match History'!AB:AB,'Match History'!A:A,">=10/01/2022 00:00",'Match History'!A:A,"<=12/31/2022 23:59",'Match History'!Z:Z,B6) +SUMIFS('Match History'!AF:AF,'Match History'!A:A,">=10/01/2022 00:00",'Match History'!A:A,"<=12/31/2022 23:59",'Match History'!AD:AD,B6) +SUMIFS('Match History'!AJ:AJ,'Match History'!A:A,">=10/01/2022 00:00",'Match History'!A:A,"<=12/31/2022 23:59",'Match History'!AH:AH,B6) +SUMIFS('Match History'!AN:AN,'Match History'!A:A,">=10/01/2022 00:00",'Match History'!A:A,"<=12/31/2022 23:59",'Match History'!AL:AL,B6) +SUMIFS('Match History'!AX:AX,'Match History'!A:A,">=10/01/2022 00:00",'Match History'!A:A,"<=12/31/2022 23:59",'Match History'!AV:AV,B6)+SUMIFS('Match History'!BB:BB,'Match History'!A:A,">=10/01/2022 00:00",'Match History'!A:A,"<=12/31/2022 23:59",'Match History'!AZ:AZ,B6) +SUMIFS('Match History'!BF:BF,'Match History'!A:A,">=10/01/2022 00:00",'Match History'!A:A,"<=12/31/2022 23:59",'Match History'!BD:BD,B6) +SUMIFS('Match History'!BJ:BJ,'Match History'!A:A,">=10/01/2022 00:00",'Match History'!A:A,"<=12/31/2022 23:59",'Match History'!BH:BH,B6))/U6) -> 34.285714
A7: Neo | B7: neo | C7: 1055.0569 | D7: =NORMDIST(C7,1000,STDEV($C$2:$C$39)+0.00001,TRUE) -> 0.74750626 | F7: =COUNTIF('Match History'!A:BK,"neo") -> 320 | G7: PL | H7: 2fast4u | I7: - | J7: 1 | K7: 1 | L7: =AND($N7<>"no war", $N7>=DATE(2022, 12, 31)-30, $M7<>TRUE) -> TRUE | M7: FALSE | N7: {=IF(F7=0, "no war", INDEX('Match History'!A:A, MAX(MAX(('Match History'!B:B=B7)*(ROW('Match History'!B:B))),MAX(('Match History'!F:F=B7)*(ROW('Match History'!F:F))),MAX(('Match History'!J:J=B7)*(ROW('Match History'!J:J))),MAX(('Match History'!N:N=B7)*(ROW('Match History'!N:N))),MAX(('Match History'!R:R=B7)*(ROW('Match History'!R:R))),MAX(('Match History'!V:V=B7)*(ROW('Match History'!V:V))),MAX(('Match History'!Z:Z=B7)*(ROW('Match History'!Z:Z))),MAX(('Match History'!AD:AD=B7)*(ROW('Match History'!AD:AD))),MAX(('Match History'!AH:AH=B7)*(ROW('Match History'!AH:AH))),MAX(('Match History'!AL:AL=B7)*(ROW('Match History'!AL:AL))),MAX(('Match History'!AV:AV=B7)*(ROW('Match History'!AV:AV))),MAX(('Match History'!AZ:AZ=B7)*(ROW('Match History'!AZ:AZ))),MAX(('Match History'!BD:BD=B7)*(ROW('Match History'!BD:BD))),MAX(('Match History'!BH:BH=B7)*(ROW('Match History'!BH:BH)))), 1))} -> 44925.089 | O7: =(SUMIF('Match History'!B:B,B7,'Match History'!D:D)+SUMIF('Match History'!F:F,B7,'Match History'!H:H)+SUMIF('Match History'!J:J,B7,'Match History'!L:L)+SUMIF('Match History'!N:N,B7,'Match History'!P:P)+SUMIF('Match History'!R:R,B7,'Match History'!T:T)+SUMIF('Match History'!V:V,B7,'Match History'!X:X)+SUMIF('Match History'!Z:Z,B7,'Match History'!AB:AB)+SUMIF('Match History'!AD:AD,B7,'Match History'!AF:AF)+SUMIF('Match History'!AH:AH,B7,'Match History'!AJ:AJ)+SUMIF('Match History'!AL:AL,B7,'Match History'!AN:AN)+SUMIF('Match History'!AV:AV,B7,'Match History'!AX:AX)+SUMIF('Match History'!AZ:AZ,B7,'Match History'!BB:BB)+SUMIF('Match History'!BD:BD,B7,'Match History'!BF:BF)+SUMIF('Match History'!BH:BH,B7,'Match History'!BJ:BJ))/IF(F7=0,1,F7) -> 21.140625 | P7: {=MAX(MAX(IF('Match History'!B:B=B7,'Match History'!D:D,)),MAX(IF('Match History'!F:F=B7,'Match History'!H:H,)),MAX(IF('Match History'!J:J=B7,'Match History'!L:L,)),MAX(IF('Match History'!N:N=B7,'Match History'!P:P,)),MAX(IF('Match History'!R:R=B7,'Match History'!T:T,)),MAX(IF('Match History'!V:V=B7,'Match History'!X:X,)),MAX(IF('Match History'!Z:Z=B7,'Match History'!AB:AB,)),MAX(IF('Match History'!AD:AD=B7,'Match History'!AF:AF,)),MAX(IF('Match History'!AH:AH=B7,'Match History'!AJ:AJ,)),MAX(IF('Match History'!AL:AL=B7,'Match History'!AN:AN,)),MAX(IF('Match History'!AV:AV=B7,'Match History'!AX:AX,)),MAX(IF('Match History'!AZ:AZ=B7,'Match History'!BB:BB,)),MAX(IF('Match History'!BD:BD=B7,'Match History'!BF:BF,)),MAX(IF('Match History'!BH:BH=B7,'Match History'!BJ:BJ,)))} -> 48 | Q7: {=IF(F7=0,0,MIN(MIN(IF('Match History'!B:B=B7,'Match History'!D:D,999)),MIN(IF('Match History'!F:F=B7,'Match History'!H:H,999)),MIN(IF('Match History'!J:J=B7,'Match History'!L:L,999)),MIN(IF('Match History'!N:N=B7,'Match History'!P:P,999)),MIN(IF('Match History'!R:R=B7,'Match History'!T:T,999)),MIN(IF('Match History'!V:V=B7,'Match History'!X:X,999)),MIN(IF('Match History'!Z:Z=B7,'Match History'!AB:AB,999)),MIN(IF('Match History'!AD:AD=B7,'Match History'!AF:AF,999)),MIN(IF('Match History'!AH:AH=B7,'Match History'!AJ:AJ,999)),MIN(IF('Match History'!AL:AL=B7,'Match History'!AN:AN,999)),MIN(IF('Match History'!AV:AV=B7,'Match History'!AX:AX,999)),MIN(IF('Match History'!AZ:AZ=B7,'Match History'!BB:BB,999)),MIN(IF('Match History'!BD:BD=B7,'Match History'!BF:BF,999)),MIN(IF('Match History'!BH:BH=B7,'Match History'!BJ:BJ,999))))} -> 6 | R7: =COUNTIFS('Match History'!B:B,B7,'Match History'!A:A,">="&(DATE(2022,12,31)-30))+COUNTIFS('Match History'!F:F,B7,'Match History'!A:A,">="&(DATE(2022,12,31)-30))+COUNTIFS('Match History'!J:J,B7,'Match History'!A:A,">="&(DATE(2022,12,31)-30))+COUNTIFS('Match History'!N:N,B7,'Match History'!A:A,">="&(DATE(2022,12,31)-30))+COUNTIFS('Match History'!R:R,B7,'Match History'!A:A,">="&(DATE(2022,12,31)-30))+COUNTIFS('Match History'!V:V,B7,'Match History'!A:A,">="&(DATE(2022,12,31)-30))+COUNTIFS('Match History'!Z:Z,B7,'Match History'!A:A,">="&(DATE(2022,12,31)-30))+COUNTIFS('Match History'!AD:AD,B7,'Match History'!A:A,">="&(DATE(2022,12,31)-30))+COUNTIFS('Match History'!AH:AH,B7,'Match History'!A:A,">="&(DATE(2022,12,31)-30))+COUNTIFS('Match History'!AL:AL,B7,'Match History'!A:A,">="&(DATE(2022,12,31)-30))+COUNTIFS('Match History'!AV:AV,B7,'Match History'!A:A,">="&(DATE(2022,12,31)-30))+COUNTIFS('Match History'!AZ:AZ,B7,'Match History'!A:A,">="&(DATE(2022,12,31)-30))+COUNTIFS('Match History'!BD:BD,B7,'Match History'!A:A,">="&(DATE(2022,12,31)-30))+COUNTIFS('Match History'!BH:BH,B7,'Match History'!A:A,">="&(DATE(2022,12,31)-30)) -> 37 | S7: =COUNTIFS('Match History'!B:B,B7,'Match History'!A:A,">="&(DATE(2022,12,31)-365))+COUNTIFS('Match History'!F:F,B7,'Match History'!A:A,">="&(DATE(2022,12,31)-365))+COUNTIFS('Match History'!J:J,B7,'Match History'!A:A,">="&(DATE(2022,12,31)-365))+COUNTIFS('Match History'!N:N,B7,'Match History'!A:A,">="&(DATE(2022,12,31)-365))+COUNTIFS('Match History'!R:R,B7,'Match History'!A:A,">="&(DATE(2022,12,31)-365))+COUNTIFS('Match History'!V:V,B7,'Match History'!A:A,">="&(DATE(2022,12,31)-365))+COUNTIFS('Match History'!Z:Z,B7,'Match History'!A:A,">="&(DATE(2022,12,31)-365))+COUNTIFS('Match History'!AD:AD,B7,'Match History'!A:A,">="&(DATE(2022,12,31)-365))+COUNTIFS('Match History'!AH:AH,B7,'Match History'!A:A,">="&(DATE(2022,12,31)-365))+COUNTIFS('Match History'!AL:AL,B7,'Match History'!A:A,">="&(DATE(2022,12,31)-365))+COUNTIFS('Match History'!AV:AV,B7,'Match History'!A:A,">="&(DATE(2022,12,31)-365))+COUNTIFS('Match History'!AZ:AZ,B7,'Match History'!A:A,">="&(DATE(2022,12,31)-365))+COUNTIFS('Match History'!BD:BD,B7,'Match History'!A:A,">="&(DATE(2022,12,31)-365))+COUNTIFS('Match History'!BH:BH,B7,'Match History'!A:A,">="&(DATE(2022,12,31)-365)) -> 291 | T7: {=IF(F7=0,0,INDEX('Match History'!B:BK,MATCH(N7,'Match History'!A:A,0),MATCH(B7,INDEX('Match History'!B:BK,MATCH(N7,'Match History'!A:A,0),0),0)+3)-INDEX('Match History'!B:BK,MATCH(N7,'Match History'!A:A,0),MATCH(B7,INDEX('Match History'!B:BK,MATCH(N7,'Match History'!A:A,0),0),0)+1))} -> 5.2198133 | U7: =COUNTIFS('Match History'!B:B,B7,'Match History'!A:A,">="&(DATE(2022,12,31)-92)) +COUNTIFS('Match History'!F:F,B7,'Match History'!A:A,">="&(DATE(2022,12,31)-92)) +COUNTIFS('Match History'!J:J,B7,'Match History'!A:A,">="&(DATE(2022,12,31)-92)) +COUNTIFS('Match History'!N:N,B7,'Match History'!A:A,">="&(DATE(2022,12,31)-92)) +COUNTIFS('Match History'!R:R,B7,'Match History'!A:A,">="&(DATE(2022,12,31)-92)) +COUNTIFS('Match History'!V:V,B7,'Match History'!A:A,">="&(DATE(2022,12,31)-92)) +COUNTIFS('Match History'!Z:Z,B7,'Match History'!A:A,">="&(DATE(2022,12,31)-92)) +COUNTIFS('Match History'!AD:AD,B7,'Match History'!A:A,">="&(DATE(2022,12,31)-92)) +COUNTIFS('Match History'!AH:AH,B7,'Match History'!A:A,">="&(DATE(2022,12,31)-92)) +COUNTIFS('Match History'!AL:AL,B7,'Match History'!A:A,">="&(DATE(2022,12,31)-92)) +COUNTIFS('Match History'!AV:AV,B7,'Match History'!A:A,">="&(DATE(2022,12,31)-92)) +COUNTIFS('Match History'!AZ:AZ,B7,'Match History'!A:A,">="&(DATE(2022,12,31)-92)) +COUNTIFS('Match History'!BD:BD,B7,'Match History'!A:A,">="&(DATE(2022,12,31)-92)) +COUNTIFS('Match History'!BH:BH,B7,'Match History'!A:A,">="&(DATE(2022,12,31)-92)) -> 88 | V7: =IF(U7=0,0,(SUMIFS('Match History'!D:D,'Match History'!A:A,">=10/01/2022 00:00",'Match History'!A:A,"<=12/31/2022 23:59",'Match History'!B:B,B7) +SUMIFS('Match History'!H:H,'Match History'!A:A,">=10/01/2022 00:00",'Match History'!A:A,"<=12/31/2022 23:59",'Match History'!F:F,B7) +SUMIFS('Match History'!L:L,'Match History'!A:A,">=10/01/2022 00:00",'Match History'!A:A,"<=12/31/2022 23:59",'Match History'!J:J,B7) +SUMIFS('Match History'!P:P,'Match History'!A:A,">=10/01/2022 00:00",'Match History'!A:A,"<=12/31/2022 23:59",'Match History'!N:N,B7) +SUMIFS('Match History'!T:T,'Match History'!A:A,">=10/01/2022 00:00",'Match History'!A:A,"<=12/31/2022 23:59",'Match History'!R:R,B7) +SUMIFS('Match History'!X:X,'Match History'!A:A,">=10/01/2022 00:00",'Match History'!A:A,"<=12/31/2022 23:59",'Match History'!V:V,B7) +SUMIFS('Match History'!AB:AB,'Match History'!A:A,">=10/01/2022 00:00",'Match History'!A:A,"<=12/31/2022 23:59",'Match History'!Z:Z,B7) +SUMIFS('Match History'!AF:AF,'Match History'!A:A,">=10/01/2022 00:00",'Match History'!A:A,"<=12/31/2022 23:59",'Match History'!AD:AD,B7) +SUMIFS('Match History'!AJ:AJ,'Match History'!A:A,">=10/01/2022 00:00",'Match History'!A:A,"<=12/31/2022 23:59",'Match History'!AH:AH,B7) +SUMIFS('Match History'!AN:AN,'Match History'!A:A,">=10/01/2022 00:00",'Match History'!A:A,"<=12/31/2022 23:59",'Match History'!AL:AL,B7) +SUMIFS('Match History'!AX:AX,'Match History'!A:A,">=10/01/2022 00:00",'Match History'!A:A,"<=12/31/2022 23:59",'Match History'!AV:AV,B7)+SUMIFS('Match History'!BB:BB,'Match History'!A:A,">=10/01/2022 00:00",'Match History'!A:A,"<=12/31/2022 23:59",'Match History'!AZ:AZ,B7) +SUMIFS('Match History'!BF:BF,'Match History'!A:A,">=10/01/2022 00:00",'Match History'!A:A,"<=12/31/2022 23:59",'Match History'!BD:BD,B7) +SUMIFS('Match History'!BJ:BJ,'Match History'!A:A,">=10/01/2022 00:00",'Match History'!A:A,"<=12/31/2022 23:59",'Match History'!BH:BH,B7))/U7) -> 20.784091
